rostopic pub -1 /cord_ros std_msgs/Float64MultiArray "data: [130, 0.0, 0.0, 0.0, 0.0, -90]"

ls -l /dev | grep ACM

sudo chmod 666 /dev/ttyACM0

rosrun rosserial_python serial_node.py /dev/ttyACM0 _baud:=115200

ls -l /dev | grep ACM



rostopic echo puntos_dy
rostopic echo joint_states
rostopic echo cord_dy
rostopic echo pos_dy

python3 trayectoria35.py
python3 modo_lectura15.py
python3 publicacion_posicion_real3.py
python3 controlador_rutina_prueba3.py

roslaunch cobot_controladores preubaInicio9.launch


roslaunch rosbridge_server rosbridge_websocket.launch _port:=9091

Para correr la pagina
	npm run dev 				//local
	npm run dev -- --host			//Servidor
	
para darle permiso a todas las carpetas

	find . -type f -name "*.py" -exec chmod +x {} \;
	
Subir a git

	git add .
	git commit -m ""
	git push origin main
	
	
bajar cambios de github:
forzar (por si he hecho cambios locales y no me interesa perderlo forzando el repositorio bajado)

# asegurate de estar en la rama correcta, por ej. main
	git fetch origin				//descarga la última información del remoto.
	git reset --hard origin/main			//descarta cualquier cambio local y deja tu copia idéntica al remoto
	
bajar normal:
	git pull
	
	
	
roscd pilz_industrial_motion_planner


sudo apt update
sudo apt install ros-noetic-pilz-industrial-motion

rostopic pub -1 /rutina std_msgs/Bool "data: true"


move_group/display_planned_path



[ERROR] [1760460027.520426]: bad callback: <function callback_sequence_result at 0x7fea94efe3a0>
Traceback (most recent call last):
  File "/opt/ros/noetic/lib/python3/dist-packages/rospy/topics.py", line 750, in _invoke_callback
    cb(msg)
  File "controlador_rutina_prueba_rutina.py", line 41, in callback_sequence_result
    sequence = msg.result.response.planned_trajectory_sequence
AttributeError: 'MotionSequenceResponse' object has no attribute 'planned_trajectory_sequence'

